<?xml version='1.0'?>

<robot name="my_robot" xmlns:xacro="http://www.ros.org/wiki/xacro">
  <xacro:include filename="$(find my_robot)/urdf/common_materials.xacro"/>
  <xacro:include filename="$(find my_robot)/urdf/my_robot.gazebo" />
  <xacro:include filename="$(find my_robot)/urdf/my_robot.transmission.xacro" />
  <link name="robot_footprint"></link>

  <joint name="robot_footprint_joint" type="fixed">
    <origin xyz="0 0 0" rpy="0 0 0" />
    <parent link="robot_footprint"/>
    <child link="chassis" />
  </joint>

  <link name='chassis'>
    <pose>0 0 0.1 0 0 0</pose>

    <inertial>
      <mass value="15.0"/>
      <origin xyz="0.0 0 0" rpy=" 0 0 0"/>
      <inertia
          ixx="0.1" ixy="0" ixz="0"
          iyy="0.1" iyz="0"
          izz="0.1"
      />
    </inertial>

    <collision name='collision'>
      <origin xyz="0 0 0" rpy=" 0 0 0"/> 
      <geometry>
        <box size=".4 .2 .1"/>
      </geometry>
    </collision>

    <visual name='chassis_visual'>
      <origin xyz="0 0 0" rpy=" 0 0 0"/>
      <geometry>
        <box size=".4 .2 .1"/>
      </geometry>
    </visual>


    <collision name='back_caster_collision'>
      <origin xyz="-0.15 0 -0.05" rpy=" 0 0 0"/>
      <geometry>
        <sphere radius="0.0499"/>
      </geometry>
    </collision>

    <visual name='back_caster_visual'>
      <origin xyz="-0.15 0 -0.05" rpy=" 0 0 0"/>
      <geometry>
        <sphere radius="0.05"/>
      </geometry>
    </visual>

    <collision name='front_caster_collision'>
      <origin xyz="0.15 0 -0.05" rpy=" 0 0 0"/>
      <geometry>
        <sphere radius="0.0499"/>
      </geometry>
    </collision>

    <visual name='front_caster_visual'>
      <origin xyz="0.15 0 -0.05" rpy=" 0 0 0"/>
      <geometry>
        <sphere radius="0.05"/>
      </geometry>
    </visual>
  </link>

  <joint type="continuous" name="left_wheel_hinge">
    <origin xyz="0 0.15 0" rpy="0 0 0"/>
    <child link="left_wheel"/>
    <parent link="chassis"/>
    <axis xyz="0 1 0" rpy="0 0 0"/>
    <limit effort="10000" velocity="1000"/>
    <dynamics damping="1.0" friction="1.0"/>
  </joint>

  <link name='left_wheel'>
    <inertial>
      <mass value="5.0"/>
      <origin xyz="0 0 0" rpy="0 1.5707 1.5707"/>
      <inertia
          ixx="0.1" ixy="0" ixz="0"
          iyy="0.1" iyz="0"
          izz="0.1"
      />
    </inertial>

    <collision name='left_wheel_collision'>
      <origin xyz="0 0 0" rpy="0 1.5707 1.5707"/>
      <geometry>
        <cylinder radius="0.1" length="0.05"/>
      </geometry>
    </collision>

    <visual name='left_wheel_visual'>
      <origin xyz="0 0 0" rpy="0 1.5707 1.5707"/>
      <geometry>
        <cylinder radius="0.1" length="0.05"/>
      </geometry>
    </visual>
  </link>

  <joint type="continuous" name="right_wheel_hinge">
    <origin xyz="0 -0.15 0" rpy="0 0 0"/>
    <child link="right_wheel"/>
    <parent link="chassis"/>
    <axis xyz="0 1 0" rpy="0 0 0"/>
    <limit effort="10000" velocity="1000"/>
    <dynamics damping="1.0" friction="1.0"/>
  </joint>

  <link name='right_wheel'>
    <inertial>
      <mass value="5.0"/>
      <origin xyz="0 0 0" rpy="0 1.5707 1.5707"/>
      <inertia
          ixx="0.1" ixy="0" ixz="0"
          iyy="0.1" iyz="0"
          izz="0.1"
      />
    </inertial>

    <collision name='right_wheel_collision'>
      <origin xyz="0 0 0" rpy="0 1.5707 1.5707"/>
      <geometry>
        <cylinder radius="0.1" length="0.05"/>
      </geometry>
    </collision>

    <visual name='right_wheel_visual'>
      <origin xyz="0 0 0" rpy="0 1.5707 1.5707"/>
      <geometry>
        <cylinder radius="0.1" length="0.05"/>
      </geometry>
    </visual>
  </link>
  <link name="camera_link">
    <inertial>
      <origin xyz="0.0 0.0 0.0" rpy="0.0 0.0 0.0"/>
      <mass value="0.1"/>
      <inertia ixx="1e-6" ixy="0.0" ixz="0.0" iyy="1e-6" iyz="0.0" izz="1e-6"/>
    </inertial>
    <visual name="camera_visual">
      <origin xyz="0.0 0.0 0.0" rpy="0.0 0.0 0.0"/>
      <geometry>
        <box size="0.05 0.05 0.05"/>
      </geometry>
    </visual>
    <collision>
      <origin xyz="0.0 0.0 0.0" rpy="0.0 0.0 0.0"/>
      <geometry>
        <box size="0.05 0.05 0.05"/>
      </geometry>
    </collision>
  </link>
  <joint name="camera_joint" type="fixed">
    <origin xyz="0.2 0.0 0.0" rpy="0.0 0.0 0.0"/>
    <parent link="chassis"/>
    <child link="camera_link"/>
    <axis xyz="0 1 0"/>
  </joint>
  <link name="hokuyo">
    <inertial>
      <origin xyz="0.0 0.0 0.0" rpy="0.0 0.0 0.0"/>
      <mass value="1e-5"/>
      <inertia ixx="0.0" ixy="0.0" ixz="0.0" iyy="0.0" iyz="0.0" izz="0.0"/>
    </inertial>
    <visual name="hokuyo_visual">
      <origin xyz="0.0 0.0 0.0" rpy="0.0 0.0 0.0"/>
      <geometry>
        <mesh filename="package://my_robot/meshes/hokuyo.dae"/>
      </geometry>
    </visual>
    <collision>
      <origin xyz="0.0 0.0 0.0" rpy="0.0 0.0 0.0"/>
      <geometry>
        <box size="0.1 0.1 0.1"/>
      </geometry>
    </collision>
  </link>
  <joint name="hokuyo_joint" type="fixed">
    <origin xyz="0.15 0.0 0.1" rpy="0.0 0.0 0.0"/>
    <parent link="chassis"/>
    <child link="hokuyo"/>
    <axis xyz="0 1 0"/>
  </joint>
    <link name="my_robot_base_link">
      <visual>
        <origin xyz="0 0 0" rpy="0 0 0"/>
        <geometry>
          <mesh scale="0.01 0.01 0.01" filename="package://my_robot/meshes/visual/base_link.stl"/>
        </geometry>
        <xacro:material_fanuc_gray28 />
      </visual>
      <collision>
        <origin xyz="0 0 0" rpy="0 0 0"/>
        <geometry>
          <mesh scale="0.01 0.01 0.01" filename="package://my_robot/meshes/collision/base_link.stl"/>
        </geometry>
      </collision>
    </link>
    <link name="my_robot_link_1">
      <visual>
        <origin xyz="0 0 0" rpy="0 0 0"/>
        <geometry>
          <mesh scale="0.01 0.01 0.01" filename="package://my_robot/meshes/visual/link_1.stl"/>
        </geometry>
        <xacro:material_fanuc_yellow />
      </visual>
      <collision>
        <origin xyz="0 0 0" rpy="0 0 0"/>
        <geometry>
          <mesh scale="0.01 0.01 0.01" filename="package://my_robot/meshes/collision/link_1.stl"/>
        </geometry>
      </collision>
    </link>
    <link name="my_robot_link_2">
      <visual>
        <origin xyz="0 0 0" rpy="1.57 0 1.57"/>
        <geometry>
          <mesh scale="0.01 0.01 0.01" filename="package://my_robot/meshes/visual/link_2.stl"/>
        </geometry>
        <xacro:material_fanuc_yellow />
      </visual>
      <collision>
        <origin xyz="0 0 0" rpy="1.57 0 1.57"/>
        <geometry>
          <mesh scale="0.01 0.01 0.01" filename="package://my_robot/meshes/collision/link_2.stl"/>
        </geometry>
      </collision>
    </link>
    <link name="my_robot_link_3">
      <visual>
        <origin xyz="0 0 0" rpy="1.57 0 1.57"/>
        <geometry>
          <mesh scale="0.01 0.01 0.01" filename="package://my_robot/meshes/visual/link_3.stl"/>
        </geometry>
        <xacro:material_fanuc_yellow />
      </visual>
      <collision>
        <origin xyz="0 0 0" rpy="1.57 0 1.57"/>
        <geometry>
          <mesh scale="0.01 0.01 0.01" filename="package://my_robot/meshes/collision/link_3.stl"/>
        </geometry>
      </collision>
    </link>
    <link name="my_robot_link_4">
      <visual>
        <origin xyz="0 0 0" rpy="0 -1.57 0"/>
        <geometry>
          <mesh scale="0.01 0.01 0.01" filename="package://my_robot/meshes/visual/link_4.stl"/>
        </geometry>
        <xacro:material_fanuc_yellow />
      </visual>
      <collision>
        <origin xyz="0 0 0" rpy="0 -1.57 0"/>
        <geometry>
          <mesh scale="0.01 0.01 0.01" filename="package://my_robot/meshes/collision/link_4.stl"/>
        </geometry>
      </collision>
    </link>
        <link name="my_robot_link_5">
      <visual>
        <origin xyz="0 0 0" rpy="0 -1.57 0"/>
        <geometry>
          <mesh scale="0.01 0.01 0.01" filename="package://my_robot/meshes/visual/link_5.stl"/>
        </geometry>
        <xacro:material_fanuc_yellow />
      </visual>
      <collision>
        <origin xyz="0 0 0" rpy="0 -1.57 0"/>
        <geometry>
          <mesh scale="0.01 0.01 0.01" filename="package://my_robot/meshes/collision/link_5.stl"/>
        </geometry>
      </collision>
    </link>
        <link name="my_robot_link_6">
      <visual>
        <origin xyz="0 0 0" rpy="3.14 0 0"/>
        <geometry>
          <mesh scale="0.01 0.01 0.01" filename="package://my_robot/meshes/visual/link_6.stl"/>
        </geometry>
        <xacro:material_fanuc_yellow />
      </visual>
      <collision>
        <origin xyz="0 0 0" rpy="3.14 0 0"/>
        <geometry>
          <mesh scale="0.01 0.01 0.01" filename="package://my_robot/meshes/collision/link_6.stl"/>
        </geometry>
      </collision>
    </link>


    <!-- joints: main serial chain -->
    <joint name="my_robot_arm_base" type="fixed">
      <origin xyz="0.0 0 0.05" rpy="0.0 0.0 -1.5707"/>
      <parent link="chassis"/>
      <child link="my_robot_base_link"/>
      <axis xyz="0.0 0.0 0.0"/>
      <limit lower="0.0" upper="0.0" effort="0.0" velocity="0.0"/>
    </joint>
    <joint name="my_robot_joint_1" type="fixed">
      <origin xyz="0 0 0.175" rpy="0 0 0" />
      <parent link="my_robot_base_link" />
      <child link="my_robot_link_1" />
      <axis xyz="0 0 1" />
      <limit effort="0" lower="-2.965" upper="2.965" velocity="7.85" />
    </joint>
    <joint name="my_robot_joint_2" type="fixed">
      <origin xyz="0 0 0.1065" rpy="0 0 0"/>
      <parent link="my_robot_link_1" />
      <child link="my_robot_link_2" />
      <axis xyz="1 0 0" />
      <limit effort="0" lower="-1.745329" upper="2.530727" velocity="6.63" />
    </joint>
    <joint name="my_robot_joint_3" type="fixed">
      <origin xyz="0 0 0.234" rpy="0 0 0"/>
      <parent link="my_robot_link_2" />
      <child link="my_robot_link_3" />
      <axis xyz="1 0 0" />
      <limit effort="0" lower="-2.450966" upper="4.886922" velocity="9.08" />
    </joint>
    <joint name="my_robot_joint_4" type="fixed">
      <origin xyz="0 0.13 0.032" rpy="0 0 0"/>
      <parent link="my_robot_link_3" />
      <child link="my_robot_link_4" />
      <axis xyz="0 -1 0" />
      <limit effort="0" lower="-2.450966" upper="2.450966" velocity="9.08" />
    </joint>
    <joint name="my_robot_joint_5" type="fixed">
      <origin xyz="-0.0035 0.228575 0" rpy="0 0 0"/>
      <parent link="my_robot_link_4" />
      <child link="my_robot_link_5" />
      <axis xyz="1 0 0" />
      <limit effort="0" lower="-2.450966" upper="2.450966" velocity="9.08" />
    </joint>
    <joint name="my_robot_joint_6" type="fixed">
      <origin xyz="0 0 -0.076" rpy="0 0 0"/>
      <parent link="my_robot_link_5" />
      <child link="my_robot_link_6" />
      <axis xyz="0 0 1" />
      <limit effort="0" lower="-2.450966" upper="2.450966" velocity="9.08" />
    </joint>

    <joint name="camera_optical_joint" type="fixed">
      <origin xyz="0 0 0" rpy="-1.5707 0 -1.5707"/>
      <parent link="camera_link"/>
      <child link="camera_link_optical"/>
    </joint>

    <link name="camera_link_optical">
    </link>

      <gazebo reference="left_wheel">
    <material>Gazebo/Green</material>
    </gazebo>
    <gazebo reference="right_wheel">
    <material>Gazebo/Green</material>
    </gazebo>
</robot>

